<!--
Walker2D model for `Walker2d-v5`, based on openai/gym/Walker2d
modified by @kallinteris-Andreas
  - To not require `coordinate="global"`
  - Set feet friction to 1.9
-->
<mujoco model="walker2d">
  <compiler angle="degree" inertiafromgeom="true"/>
  <default>
    <joint armature="0.01" damping=".1" limited="true"/>
    <geom conaffinity="0" condim="3" contype="1" density="1000" friction=".7 .1 .1" rgba="0.8 0.6 .4 1"/>
  </default>
  <option integrator="RK4" timestep="0.002"/>
  <worldbody>
    <light cutoff="100" diffuse="1 1 1" dir="-0 0 -1.3" directional="true" exponent="1" pos="0 0 1.3" specular=".1 .1 .1"/>
    <geom conaffinity="1" condim="3" name="floor" pos="0 0 0" rgba="0.8 0.9 0.8 1" size="40 40 40" type="plane" material="MatPlane"/>
    <!-- 계단 추가 높이0.18m, 깊이0.3m, 갯수 50개-->
    <geom conaffinity="1" condim="3" name="stair_1" pos="2.15 0 0.09" size="0.15 5.0 0.09" type="box" rgba="0.9 0.5 0.5 1"/>
    <geom conaffinity="1" condim="3" name="stair_2" pos="2.45 0 0.27" size="0.15 5.0 0.09" type="box" rgba="0.9 0.5 0.5 1"/>
    <geom conaffinity="1" condim="3" name="stair_3" pos="2.75 0 0.45" size="0.15 5.0 0.09" type="box" rgba="0.9 0.5 0.5 1"/>
    <geom conaffinity="1" condim="3" name="stair_4" pos="3.05 0 0.63" size="0.15 5.0 0.09" type="box" rgba="0.9 0.5 0.5 1"/>
    <geom conaffinity="1" condim="3" name="stair_5" pos="3.35 0 0.81" size="0.15 5.0 0.09" type="box" rgba="0.9 0.5 0.5 1"/>
    <geom conaffinity="1" condim="3" name="stair_6" pos="3.65 0 0.99" size="0.15 5.0 0.09" type="box" rgba="0.9 0.5 0.5 1"/>
    <geom conaffinity="1" condim="3" name="stair_7" pos="3.95 0 1.17" size="0.15 5.0 0.09" type="box" rgba="0.9 0.5 0.5 1"/>
    <geom conaffinity="1" condim="3" name="stair_8" pos="4.25 0 1.35" size="0.15 5.0 0.09" type="box" rgba="0.9 0.5 0.5 1"/>
    <geom conaffinity="1" condim="3" name="stair_9" pos="4.55 0 1.53" size="0.15 5.0 0.09" type="box" rgba="0.9 0.5 0.5 1"/>
    <geom conaffinity="1" condim="3" name="stair_10" pos="4.85 0 1.71" size="0.15 5.0 0.09" type="box" rgba="0.9 0.5 0.5 1"/>
    <geom conaffinity="1" condim="3" name="stair_11" pos="5.15 0 1.89" size="0.15 5.0 0.09" type="box" rgba="0.9 0.5 0.5 1"/>
    <geom conaffinity="1" condim="3" name="stair_12" pos="5.45 0 2.07" size="0.15 5.0 0.09" type="box" rgba="0.9 0.5 0.5 1"/>
    <geom conaffinity="1" condim="3" name="stair_13" pos="5.75 0 2.25" size="0.15 5.0 0.09" type="box" rgba="0.9 0.5 0.5 1"/>
    <geom conaffinity="1" condim="3" name="stair_14" pos="6.05 0 2.43" size="0.15 5.0 0.09" type="box" rgba="0.9 0.5 0.5 1"/>
    <geom conaffinity="1" condim="3" name="stair_15" pos="6.35 0 2.61" size="0.15 5.0 0.09" type="box" rgba="0.9 0.5 0.5 1"/>
    <geom conaffinity="1" condim="3" name="stair_16" pos="6.65 0 2.79" size="0.15 5.0 0.09" type="box" rgba="0.9 0.5 0.5 1"/>
    <geom conaffinity="1" condim="3" name="stair_17" pos="6.95 0 2.97" size="0.15 5.0 0.09" type="box" rgba="0.9 0.5 0.5 1"/>
    <geom conaffinity="1" condim="3" name="stair_18" pos="7.25 0 3.15" size="0.15 5.0 0.09" type="box" rgba="0.9 0.5 0.5 1"/>
    <geom conaffinity="1" condim="3" name="stair_19" pos="7.55 0 3.33" size="0.15 5.0 0.09" type="box" rgba="0.9 0.5 0.5 1"/>
    <geom conaffinity="1" condim="3" name="stair_20" pos="7.85 0 3.51" size="0.15 5.0 0.09" type="box" rgba="0.9 0.5 0.5 1"/>
    <geom conaffinity="1" condim="3" name="stair_21" pos="8.15 0 3.69" size="0.15 5.0 0.09" type="box" rgba="0.9 0.5 0.5 1"/>
    <geom conaffinity="1" condim="3" name="stair_22" pos="8.45 0 3.87" size="0.15 5.0 0.09" type="box" rgba="0.9 0.5 0.5 1"/>
    <geom conaffinity="1" condim="3" name="stair_23" pos="8.75 0 4.05" size="0.15 5.0 0.09" type="box" rgba="0.9 0.5 0.5 1"/>
    <geom conaffinity="1" condim="3" name="stair_24" pos="9.05 0 4.23" size="0.15 5.0 0.09" type="box" rgba="0.9 0.5 0.5 1"/>
    <geom conaffinity="1" condim="3" name="stair_25" pos="9.35 0 4.41" size="0.15 5.0 0.09" type="box" rgba="0.9 0.5 0.5 1"/>
    <geom conaffinity="1" condim="3" name="stair_26" pos="9.65 0 4.59" size="0.15 5.0 0.09" type="box" rgba="0.9 0.5 0.5 1"/>
    <geom conaffinity="1" condim="3" name="stair_27" pos="9.95 0 4.77" size="0.15 5.0 0.09" type="box" rgba="0.9 0.5 0.5 1"/>
    <geom conaffinity="1" condim="3" name="stair_28" pos="10.25 0 4.95" size="0.15 5.0 0.09" type="box" rgba="0.9 0.5 0.5 1"/>
    <geom conaffinity="1" condim="3" name="stair_29" pos="10.55 0 5.13" size="0.15 5.0 0.09" type="box" rgba="0.9 0.5 0.5 1"/>
    <geom conaffinity="1" condim="3" name="stair_30" pos="10.85 0 5.31" size="0.15 5.0 0.09" type="box" rgba="0.9 0.5 0.5 1"/>
    <geom conaffinity="1" condim="3" name="stair_31" pos="11.15 0 5.49" size="0.15 5.0 0.09" type="box" rgba="0.9 0.5 0.5 1"/>
    <geom conaffinity="1" condim="3" name="stair_32" pos="11.45 0 5.67" size="0.15 5.0 0.09" type="box" rgba="0.9 0.5 0.5 1"/>
    <geom conaffinity="1" condim="3" name="stair_33" pos="11.75 0 5.85" size="0.15 5.0 0.09" type="box" rgba="0.9 0.5 0.5 1"/>
    <geom conaffinity="1" condim="3" name="stair_34" pos="12.05 0 6.03" size="0.15 5.0 0.09" type="box" rgba="0.9 0.5 0.5 1"/>
    <geom conaffinity="1" condim="3" name="stair_35" pos="12.35 0 6.21" size="0.15 5.0 0.09" type="box" rgba="0.9 0.5 0.5 1"/>
    <geom conaffinity="1" condim="3" name="stair_36" pos="12.65 0 6.39" size="0.15 5.0 0.09" type="box" rgba="0.9 0.5 0.5 1"/>
    <geom conaffinity="1" condim="3" name="stair_37" pos="12.95 0 6.57" size="0.15 5.0 0.09" type="box" rgba="0.9 0.5 0.5 1"/>
    <geom conaffinity="1" condim="3" name="stair_38" pos="13.25 0 6.75" size="0.15 5.0 0.09" type="box" rgba="0.9 0.5 0.5 1"/>
    <geom conaffinity="1" condim="3" name="stair_39" pos="13.55 0 6.93" size="0.15 5.0 0.09" type="box" rgba="0.9 0.5 0.5 1"/>
    <geom conaffinity="1" condim="3" name="stair_40" pos="13.85 0 7.11" size="0.15 5.0 0.09" type="box" rgba="0.9 0.5 0.5 1"/>
    <geom conaffinity="1" condim="3" name="stair_41" pos="14.15 0 7.29" size="0.15 5.0 0.09" type="box" rgba="0.9 0.5 0.5 1"/>
    <geom conaffinity="1" condim="3" name="stair_42" pos="14.45 0 7.47" size="0.15 5.0 0.09" type="box" rgba="0.9 0.5 0.5 1"/>
    <geom conaffinity="1" condim="3" name="stair_43" pos="14.75 0 7.65" size="0.15 5.0 0.09" type="box" rgba="0.9 0.5 0.5 1"/>
    <geom conaffinity="1" condim="3" name="stair_44" pos="15.05 0 7.83" size="0.15 5.0 0.09" type="box" rgba="0.9 0.5 0.5 1"/>
    <geom conaffinity="1" condim="3" name="stair_45" pos="15.35 0 8.01" size="0.15 5.0 0.09" type="box" rgba="0.9 0.5 0.5 1"/>
    <geom conaffinity="1" condim="3" name="stair_46" pos="15.65 0 8.19" size="0.15 5.0 0.09" type="box" rgba="0.9 0.5 0.5 1"/>
    <geom conaffinity="1" condim="3" name="stair_47" pos="15.95 0 8.37" size="0.15 5.0 0.09" type="box" rgba="0.9 0.5 0.5 1"/>
    <geom conaffinity="1" condim="3" name="stair_48" pos="16.25 0 8.55" size="0.15 5.0 0.09" type="box" rgba="0.9 0.5 0.5 1"/>
    <geom conaffinity="1" condim="3" name="stair_49" pos="16.55 0 8.73" size="0.15 5.0 0.09" type="box" rgba="0.9 0.5 0.5 1"/>
    <geom conaffinity="1" condim="3" name="stair_50" pos="16.85 0 8.91" size="0.15 5.0 0.09" type="box" rgba="0.9 0.5 0.5 1"/>
    
    <body name="torso" pos="0 0 1.25">
      <camera name="track" mode="trackcom" pos="0 -3 -0.25" xyaxes="1 0 0 0 0 1"/>
      <joint armature="0" axis="1 0 0" damping="0" limited="false" name="rootx" pos="0 0 -1.25" stiffness="0" type="slide"/>
      <joint armature="0" axis="0 0 1" damping="0" limited="false" name="rootz" pos="0 0 -1.25" ref="1.25" stiffness="0" type="slide"/>
      <joint armature="0" axis="0 1 0" damping="0" limited="false" name="rooty" pos="0 0 0" stiffness="0" type="hinge"/>
      <geom friction="0.9" name="torso_geom" size="0.050000000000000003 0.19999999999999996" type="capsule"/>
      <body name="thigh" pos="0 0 -0.19999999999999996">
        <joint axis="0 -1 0" name="thigh_joint" pos="0 0 0" range="-150 0" type="hinge"/>
        <geom friction="0.9" pos="0 0 -0.22500000000000009" name="thigh_geom" size="0.050000000000000003 0.22500000000000003" type="capsule"/>
        <body name="leg" pos="0 0 -0.70000000000000007">
          <joint axis="0 -1 0" name="leg_joint" pos="0 0 0.25" range="-150 0" type="hinge"/>
          <geom friction="0.9" name="leg_geom" size="0.040000000000000001 0.25" type="capsule"/>
          <body name="foot" pos="0.20000000000000001 0 -0.34999999999999998">
            <joint axis="0 -1 0" name="foot_joint" pos="-0.20000000000000001 0 0.10000000000000001" range="-45 45" type="hinge"/>
            <geom friction="1.9" pos="-0.10000000000000001 0 0.10000000000000001" quat="0.70710678118654757 0 -0.70710678118654746 0" name="foot_geom" size="0.059999999999999998 0.10000000000000001" type="capsule"/>
          </body>
        </body>
      </body>
      <!-- copied and then replace thigh->thigh_left, leg->leg_left, foot->foot_right -->
      <body name="thigh_left" pos="0 0 -0.19999999999999996">
        <joint axis="0 -1 0" name="thigh_left_joint" pos="0 0 0" range="-150 0" type="hinge"/>
        <geom friction="0.9" name="thigh_left_geom" rgba=".7 .3 .6 1" size="0.050000000000000003 0.22500000000000003" pos="0 0 -0.22500000000000009" type="capsule"/>
        <body name="leg_left" pos="0 0 -0.70000000000000007">
          <joint axis="0 -1 0" name="leg_left_joint" pos="0 0 0.25" range="-150 0" type="hinge"/>
          <geom friction="0.9" name="leg_left_geom" rgba=".7 .3 .6 1" size="0.040000000000000001 0.25" type="capsule"/>
          <body name="foot_left" pos="0.20000000000000001 0 -0.34999999999999998">
            <joint axis="0 -1 0" name="foot_left_joint" pos="-0.20000000000000001 0 0.10000000000000001" range="-45 45" type="hinge"/>
            <geom friction="1.9" name="foot_left_geom" rgba=".7 .3 .6 1" size="0.059999999999999998 0.10000000000000001" pos="-0.10000000000000001 0 0.10000000000000001" type="capsule" quat="0.70710678118654757 0 -0.70710678118654746 0"/>
          </body>
        </body>
      </body>
    </body>
  </worldbody>
  <actuator>
    <!-- <motor joint="torso_joint" ctrlrange="-100.0 100.0" isctrllimited="true"/>-->
    <motor ctrllimited="true" ctrlrange="-1.0 1.0" gear="100" joint="thigh_joint"/>
    <motor ctrllimited="true" ctrlrange="-1.0 1.0" gear="100" joint="leg_joint"/>
    <motor ctrllimited="true" ctrlrange="-1.0 1.0" gear="100" joint="foot_joint"/>
    <motor ctrllimited="true" ctrlrange="-1.0 1.0" gear="100" joint="thigh_left_joint"/>
    <motor ctrllimited="true" ctrlrange="-1.0 1.0" gear="100" joint="leg_left_joint"/>
    <motor ctrllimited="true" ctrlrange="-1.0 1.0" gear="100" joint="foot_left_joint"/>
    <!-- <motor joint="finger2_rot" ctrlrange="-20.0 20.0" isctrllimited="true"/>-->
  </actuator>
    <asset>
        <texture type="skybox" builtin="gradient" rgb1=".4 .5 .6" rgb2="0 0 0"
            width="100" height="100"/>
        <texture builtin="flat" height="1278" mark="cross" markrgb="1 1 1" name="texgeom" random="0.01" rgb1="0.8 0.6 0.4" rgb2="0.8 0.6 0.4" type="cube" width="127"/>
        <texture builtin="checker" height="100" name="texplane" rgb1="0 0 0" rgb2="0.8 0.8 0.8" type="2d" width="100"/>
        <material name="MatPlane" reflectance="0.5" shininess="1" specular="1" texrepeat="60 60" texture="texplane"/>
        <material name="geom" texture="texgeom" texuniform="true"/>
    </asset>
</mujoco>
